{
 "cells": [
  {
   "cell_type": "code",
   "execution_count": null,
   "id": "77f6d49e-978d-41eb-a854-cb45d0ad338a",
   "metadata": {},
   "outputs": [],
   "source": [
    "#12th Feb Assignment Solution"
   ]
  },
  {
   "cell_type": "code",
   "execution_count": null,
   "id": "9409009a-6e47-4414-8a42-26f209e826bd",
   "metadata": {},
   "outputs": [],
   "source": [
    "#Ans 1\n",
    "'''\n",
    "An exception is an event, which occurs during the execution of a program that disrupts the normal flow of the program's \n",
    "instructions. In general, when a Python script encounters a situation that it cannot cope with, it raises an exception. \n",
    "An exception is a Python object that represents an error.\n",
    "\n",
    "An error is an issue in a program that prevents the program from completing its task. \n",
    "In comparison, an exception is a condition that interrupts the normal flow of the program. \n",
    "Both errors and exceptions are a type of runtime error, which means they occur during the execution of a program.'''"
   ]
  },
  {
   "cell_type": "code",
   "execution_count": null,
   "id": "67dd718c-1422-48e7-bbe7-7f49ced87065",
   "metadata": {},
   "outputs": [],
   "source": []
  },
  {
   "cell_type": "code",
   "execution_count": null,
   "id": "ddff8bde-7a24-403f-9d3a-49fba50f5708",
   "metadata": {},
   "outputs": [],
   "source": [
    "#Ans 2\n",
    "'''If the exception is not handled by an except clause,\n",
    "the exception is re-raised after the finally clause has been executed.\n",
    "'''\n",
    "divide_numbers = 7 / 0\n",
    "prit(divide_numbers)\n",
    "\n",
    "'''\n",
    "Output:\n",
    "ZeroDivisionError                         Traceback (most recent call last)\n",
    "Cell In[3], line 5\n",
    "      1 #Ans 2\n",
    "      2 '''If the exception is not handled by an except clause,\n",
    "      3 the exception is re-raised after the finally clause has been executed.\n",
    "      4 '''\n",
    "----> 5 divide_numbers = 7 / 0\n",
    "      6 prit(divide_numbers)\n",
    "\n",
    "ZeroDivisionError: division by zero\n",
    "'''"
   ]
  },
  {
   "cell_type": "code",
   "execution_count": null,
   "id": "de61ec8b-f3fa-4a82-8091-9bedabe02d4e",
   "metadata": {},
   "outputs": [],
   "source": []
  },
  {
   "cell_type": "code",
   "execution_count": null,
   "id": "a27ae1d3-564e-4e48-83cf-1db9a961cec1",
   "metadata": {},
   "outputs": [],
   "source": [
    "#Ans 3\n",
    "'''The try and except Block: Handling Exceptions\n",
    "The try and except block in Python is used to catch and handle exceptions. \n",
    "Python executes code following the try statement as a “normal” part of the program. \n",
    "The code that follows the except statement is the program’s response to any exceptions in the preceding try clause.\n",
    "'''\n",
    "try:\n",
    "    numerator = 10\n",
    "    denominator = 0\n",
    "\n",
    "    result = numerator/denominator\n",
    "\n",
    "    print(result)\n",
    "except:\n",
    "    print(\"Error: Denominator cannot be 0.\")\n",
    "\n",
    "#Output: Error: Denominator cannot be 0. \n"
   ]
  },
  {
   "cell_type": "code",
   "execution_count": null,
   "id": "7c8ca1cc-b648-4497-b1cb-94fa79f1980f",
   "metadata": {},
   "outputs": [],
   "source": []
  },
  {
   "cell_type": "code",
   "execution_count": null,
   "id": "da61cb65-fe8b-43c8-9077-92c6dbcd6bba",
   "metadata": {},
   "outputs": [],
   "source": [
    "#Ans 4\n",
    "'''\n",
    "Try: This block will test the excepted error to occur\n",
    "Else: If there is no exception then this block will be executed\n",
    "Finally: Finally block always gets executed either exception is generated or not\n",
    "Raise: The raise keyword is used to raise an exception. \n",
    "You can define what kind of error to raise, and the text to print to the user.\n",
    "'''\n",
    "\n",
    "# Python code to illustrate\n",
    "# working of try()\n",
    "def divide(x, y):\n",
    "\ttry:\n",
    "\t\t# Floor Division : Gives only Fractional\n",
    "\t\t# Part as Answer\n",
    "\t\tresult = x // y\n",
    "\texcept ZeroDivisionError:\n",
    "\t\tprint(\"Sorry ! You are dividing by zero \")\n",
    "\telse:\n",
    "\t\tprint(\"Yeah ! Your answer is :\", result)\n",
    "\n",
    "\n",
    "divide(3, 2)\n",
    "divide(3, 0)\n",
    "\n",
    "\n",
    "# Python code to illustrate\n",
    "# working of try()\n",
    "   \n",
    "def divide(x, y):\n",
    "    try:\n",
    "        # Floor Division : Gives only Fractional\n",
    "        # Part as Answer\n",
    "        result = x // y\n",
    "    except ZeroDivisionError:\n",
    "        print(\"Sorry ! You are dividing by zero \")\n",
    "    else:\n",
    "        print(\"Yeah ! Your answer is :\", result)\n",
    "    finally:\n",
    "        # this block is always executed\n",
    "        # regardless of exception generation.\n",
    "        print('This is always executed')\n",
    "\n",
    "        \n",
    "divide(3, 2)\n",
    "divide(3, 0)\n",
    "\n",
    "#Raise Example\n",
    "\n",
    "s = 'apple'\n",
    "\n",
    "try:\n",
    "\tnum = int(s)\n",
    "except ValueError:\n",
    "\traise ValueError(\"String can't be changed into integer\")\n"
   ]
  },
  {
   "cell_type": "code",
   "execution_count": null,
   "id": "6182a4a1-e536-42f1-b134-9b51911e3843",
   "metadata": {},
   "outputs": [],
   "source": []
  },
  {
   "cell_type": "code",
   "execution_count": 17,
   "id": "5e29340a-4f25-4bf5-9bcc-5e74e0c2b5b9",
   "metadata": {},
   "outputs": [
    {
     "name": "stdin",
     "output_type": "stream",
     "text": [
      "Enter a number:  -4\n"
     ]
    }
   ],
   "source": [
    "#Ans 5\n",
    "'''\n",
    "Custom exceptions in Python are user-defined exceptions that can be created by the programmer to handle \n",
    "specific error situations.\n",
    "They allow programmers to define their own types of exceptions based on their application requirements.\n",
    "\n",
    "There are several reasons why we need custom exceptions:\n",
    "1. Specific error handling: Custom exceptions provide more specific information about the error and help in better \n",
    "understanding and debugging of the code.\n",
    "2. Modularity: They allow for better code organization and encapsulation, as related exceptions can be grouped together.\n",
    "3. Customized error messages: Custom exceptions can include additional information or custom error messages that are\n",
    "more meaningful for the application.\n",
    "\n",
    "'''\n",
    " \n",
    "class Error(Exception):\n",
    "    \"\"\"Base class for other exceptions\"\"\"\n",
    "    pass\n",
    " \n",
    "class zerodivision(Error):\n",
    "    \"\"\"Raised when the input value is zero\"\"\"\n",
    "    pass\n",
    " \n",
    "try:\n",
    "    i_num = int(input(\"Enter a number: \"))\n",
    "    if i_num == 0:\n",
    "        raise zerodivision\n",
    "except zerodivision:\n",
    "    print(\"Input value is zero, try again!\")\n",
    "    print()"
   ]
  },
  {
   "cell_type": "code",
   "execution_count": null,
   "id": "606ce6a3-fdaa-49fb-a928-ad6f189e1309",
   "metadata": {},
   "outputs": [],
   "source": []
  },
  {
   "cell_type": "code",
   "execution_count": null,
   "id": "ced87999-fae6-4a15-b100-60e5f529f5df",
   "metadata": {},
   "outputs": [],
   "source": [
    "#Ans 6\n",
    "'''\n",
    "Let's say we have a program that calculates the average of a list of numbers. \n",
    "However, we want to raise a custom exception when the list is empty, as there is no average to calculate in such a case.\n",
    "'''\n",
    "\n",
    "class EmptyListError(Exception):\n",
    "    pass\n",
    "\n",
    "def calculate_average(numbers):\n",
    "    if not numbers:\n",
    "        raise EmptyListError(\"The list is empty. Cannot calculate average.\")\n",
    "    total = sum(numbers)\n",
    "    average = total / len(numbers)\n",
    "    return average\n",
    "\n",
    "try:\n",
    "    numbers = [1, 2, 3, 4, 5]\n",
    "    average = calculate_average(numbers)\n",
    "    print(f\"The average is: {average}\")\n",
    "    \n",
    "    empty_list = []\n",
    "    average = calculate_average(empty_list)\n",
    "    print(f\"The average is: {average}\")\n",
    "except EmptyListError as e:\n",
    "    print(str(e))\n",
    "'''\n",
    "In this example, we define a custom exception called `EmptyListError`.\n",
    "In the `calculate_average` function, we check if the list of numbers is empty. \n",
    "If it is, we raise the `EmptyListError` exception with a custom error message.\n",
    "When we call the `calculate_average` function with a non-empty list, the average is calculated and printed.\n",
    "However, when we call it with an empty list, the custom exception is raised and caught in the `except` block,\n",
    "where we print the custom error message.\n",
    "The use of a custom exception here allows for a more specific and informative error message when an empty\n",
    "list is encountered, making it easier to handle and identify the issue.\n",
    "'''   \n",
    "    "
   ]
  },
  {
   "cell_type": "code",
   "execution_count": null,
   "id": "fd07ba28-ccd6-478f-ab82-5a736539bbc7",
   "metadata": {},
   "outputs": [],
   "source": []
  }
 ],
 "metadata": {
  "kernelspec": {
   "display_name": "Python 3 (ipykernel)",
   "language": "python",
   "name": "python3"
  },
  "language_info": {
   "codemirror_mode": {
    "name": "ipython",
    "version": 3
   },
   "file_extension": ".py",
   "mimetype": "text/x-python",
   "name": "python",
   "nbconvert_exporter": "python",
   "pygments_lexer": "ipython3",
   "version": "3.10.8"
  }
 },
 "nbformat": 4,
 "nbformat_minor": 5
}
